Workbook

Sheet Supuestos
A1: MASTERING READY - MODELO FINANCIERO v2
A2: Con OpEx real, Churn modelado, Escenarios Base/Optimista
A4: COSTOS FIJOS MENSUALES (Phase 0)
A5: Servicio | B5: Tier | C5: Costo MR
A6: Render | B6: Starter | C6: 7
A7: Vercel | B7: Pro (÷4) | C7: 5
A8: Supabase | B8: Free | C8: 0
A9: Domain | B9: Namecheap | C9: 1
A10: TOTAL COGS | C10: =SUM(C6:C9) -> 13
A12: STRIPE FEES
A13: Porcentaje | B13: 0.029
A14: Fijo por transacción | B14: 0.3
A16: PRECIOS PROMEDIO POR TIER
A17: Tier | B17: Pro Mensual | C17: Neto (- Stripe)
A18: Tier 1 (US/EU/UK avg) | B18: 10.5 | C18: =B18-(B18*$B$13+$B$14) -> 9.8955
A19: LATAM avg (Tier 2-6) | B19: 5.2 | C19: =B19-(B19*$B$13+$B$14) -> 4.7492
A20: Single | B20: 5.99 | C20: =B20-(B20*$B$13+$B$14) -> 5.51629
A21: Add-on | B21: 3.99 | C21: =B21-(B21*$B$13+$B$14) -> 3.57429
A24: CHURN RATE
A25: Monthly Churn Rate | B25: 0.06 | C25: 6% mensual (industry avg 5-8%)
A26: Retention Rate | B26: =1-B25 -> 0.94
A28: MARKETING BUDGET (Growth Plan)
A29: Mes | B29: Base | C29: Optimista
A30: Mes 1 | B30: 50 | C30: 90
A31: Mes 2 | B31: 115 | C31: 200
A32: Mes 3 | B32: 110 | C32: 230
A33: Mes 4 | B33: 100 | C33: 200
A34: Mes 5 | B34: 100 | C34: 200
A35: Mes 6 | B35: 120 | C35: 250
A36: Mes 7 | B36: 120 | C36: 250
A37: Mes 8 | B37: 150 | C37: 300
A38: Mes 9 | B38: 150 | C38: 300
A39: Mes 10 | B39: 180 | C39: 350
A40: Mes 11 | B40: 180 | C40: 350
A41: Mes 12 | B41: 200 | C41: 400
A42: Total Marketing | B42: =SUM(B30:B41) -> 1575 | C42: =SUM(C30:C41) -> 3120
A44: TOOLS/SOFTWARE BUDGET
A45: Email Service (Resend/SendGrid) | B45: ~$10-30/mo | C45: Starts Month 2 for onboarding sequences
A46: Base Total Tools/Año | B46: 160 | C46: $0 M1, $10-20/mo M2-M12
A47: Optimista Total Tools/Año | B47: 240 | C47: $0 M1, $15-30/mo M2-M12

Sheet PL Base (Conservador)
A1: P&L - ESCENARIO BASE (CONSERVADOR)
A2: Incluye: Churn 6% mensual, Marketing OpEx real, crecimiento conservador
A4: Concepto | B4: M1 | C4: M2 | D4: M3 | E4: M4 | F4: M5 | G4: M6 | H4: M7 | I4: M8 | J4: M9 | K4: M10 | L4: M11 | M4: M12 | N4: TOTAL
A5: ═══ SUBSCRIBER DYNAMICS ═══
A6: New Tier 1 Subs (gross) | B6: 2 | C6: 2 | D6: 2 | E6: 2 | F6: 3 | G6: 3 | H6: 3 | I6: 4 | J6: 4 | K6: 5 | L6: 5 | M6: 6
A7: New LATAM Subs (gross) | B7: 1 | C7: 2 | D7: 3 | E7: 3 | F7: 3 | G7: 4 | H7: 5 | I7: 5 | J7: 6 | K7: 7 | L7: 8 | M7: 9
A8: Churned Tier 1 | B8: 0 | C8: =ROUND(B10*Supuestos!$B$25,0) -> 0 | D8: =ROUND(C10*Supuestos!$B$25,0) -> 0 | E8: =ROUND(D10*Supuestos!$B$25,0) -> 0 | F8: =ROUND(E10*Supuestos!$B$25,0) -> 0 | G8: =ROUND(F10*Supuestos!$B$25,0) -> 1 | H8: =ROUND(G10*Supuestos!$B$25,0) -> 1 | I8: =ROUND(H10*Supuestos!$B$25,0) -> 1 | J8: =ROUND(I10*Supuestos!$B$25,0) -> 1 | ... M8: =ROUND(L10*Supuestos!$B$25,0) -> 2
A9: Churned LATAM | B9: 0 | C9: =ROUND(B11*Supuestos!$B$25,0) -> 0 | D9: =ROUND(C11*Supuestos!$B$25,0) -> 0 | E9: =ROUND(D11*Supuestos!$B$25,0) -> 0 | F9: =ROUND(E11*Supuestos!$B$25,0) -> 1 | G9: =ROUND(F11*Supuestos!$B$25,0) -> 1 | H9: =ROUND(G11*Supuestos!$B$25,0) -> 1 | I9: =ROUND(H11*Supuestos!$B$25,0) -> 1 | J9: =ROUND(I11*Supuestos!$B$25,0) -> 1 | ... M9: =ROUND(L11*Supuestos!$B$25,0) -> 2
A10: Active Tier 1 Subs | B10: =B6 -> 2 | C10: =B10+C6-C8 -> 4 | D10: =C10+D6-D8 -> 6 | E10: =D10+E6-E8 -> 8 | F10: =E10+F6-F8 -> 11 | G10: =F10+G6-G8 -> 13 | H10: =G10+H6-H8 -> 15 | I10: =H10+I6-I8 -> 18 | J10: =I10+J6-J8 -> 21 | ... M10: =L10+M6-M8 -> 32 | N10: =M10 -> 32
A11: Active LATAM Subs | B11: =B7 -> 1 | C11: =B11+C7-C9 -> 3 | D11: =C11+D7-D9 -> 6 | E11: =D11+E7-E9 -> 9 | F11: =E11+F7-F9 -> 11 | G11: =F11+G7-G9 -> 14 | H11: =G11+H7-H9 -> 18 | I11: =H11+I7-I9 -> 22 | J11: =I11+J7-J9 -> 27 | ... M11: =L11+M7-M9 -> 45 | N11: =M11 -> 45
A12: Total Active Subs | B12: =B10+B11 -> 3 | C12: =C10+C11 -> 7 | D12: =D10+D11 -> 12 | E12: =E10+E11 -> 17 | F12: =F10+F11 -> 22 | G12: =G10+G11 -> 27 | H12: =H10+H11 -> 33 | I12: =I10+I11 -> 40 | ... N12: =N10+N11 -> 77
A13: Singles sold | B13: 1 | C13: 2 | D13: 2 | E13: 3 | F13: 3 | G13: 4 | H13: 5 | I13: 5 | J13: 6 | K13: 7 | L13: 8 | M13: 10 | N13: =SUM(B13:M13) -> 56
A14: Add-ons sold | B14: 0 | C14: 1 | D14: 1 | E14: 1 | F14: 2 | G14: 2 | H14: 3 | I14: 3 | J14: 4 | K14: 5 | L14: 6 | M14: 7 | N14: =SUM(B14:M14) -> 35
A16: ═══ REVENUE ═══
A17: MRR Tier 1 | B17: =B10*Supuestos!$B$18 -> 21 | C17: =C10*Supuestos!$B$18 -> 42 | D17: =D10*Supuestos!$B$18 -> 63 | E17: =E10*Supuestos!$B$18 -> 84 | F17: =F10*Supuestos!$B$18 -> 115.5 | G17: =G10*Supuestos!$B$18 -> 136.5 | H17: =H10*Supuestos!$B$18 -> 157.5 | I17: =I10*Supuestos!$B$18 -> 189 | ... M17: =M10*Supuestos!$B$18 -> 336 | N17: =SUM(B17:M17) -> 1921.5
A18: MRR LATAM | B18: =B11*Supuestos!$B$19 -> 5.2 | C18: =C11*Supuestos!$B$19 -> 15.6 | D18: =D11*Supuestos!$B$19 -> 31.2 | E18: =E11*Supuestos!$B$19 -> 46.8 | F18: =F11*Supuestos!$B$19 -> 57.2 | G18: =G11*Supuestos!$B$19 -> 72.8 | H18: =H11*Supuestos!$B$19 -> 93.6 | I18: =I11*Supuestos!$B$19 -> 114.4 | ... M18: =M11*Supuestos!$B$19 -> 234 | N18: =SUM(B18:M18) -> 1175.2
A19: Singles Revenue | B19: =B13*Supuestos!$B$20 -> 5.99 | C19: =C13*Supuestos!$B$20 -> 11.98 | D19: =D13*Supuestos!$B$20 -> 11.98 | E19: =E13*Supuestos!$B$20 -> 17.97 | F19: =F13*Supuestos!$B$20 -> 17.97 | G19: =G13*Supuestos!$B$20 -> 23.96 | H19: =H13*Supuestos!$B$20 -> 29.95 | I19: =I13*Supuestos!$B$20 -> 29.95 | ... M19: =M13*Supuestos!$B$20 -> 59.9 | N19: =SUM(B19:M19) -> 335.44
A20: Add-ons Revenue | B20: =B14*Supuestos!$B$21 -> 0 | C20: =C14*Supuestos!$B$21 -> 3.99 | D20: =D14*Supuestos!$B$21 -> 3.99 | E20: =E14*Supuestos!$B$21 -> 3.99 | F20: =F14*Supuestos!$B$21 -> 7.98 | G20: =G14*Supuestos!$B$21 -> 7.98 | H20: =H14*Supuestos!$B$21 -> 11.97 | I20: =I14*Supuestos!$B$21 -> 11.97 | ... M20: =M14*Supuestos!$B$21 -> 27.93 | N20: =SUM(B20:M20) -> 139.65
A21: TOTAL REVENUE | B21: =SUM(B17:B20) -> 32.19 | C21: =SUM(C17:C20) -> 73.57 | D21: =SUM(D17:D20) -> 110.17 | E21: =SUM(E17:E20) -> 152.76 | F21: =SUM(F17:F20) -> 198.65 | G21: =SUM(G17:G20) -> 241.24 | H21: =SUM(H17:H20) -> 293.02 | I21: =SUM(I17:I20) -> 345.32 | ... N21: =SUM(N17:N20) -> 3571.79
A23: ═══ COST OF REVENUE (Stripe) ═══
A24: Transactions | B24: =B12+B13+B14 -> 4 | C24: =C12+C13+C14 -> 10 | D24: =D12+D13+D14 -> 15 | E24: =E12+E13+E14 -> 21 | F24: =F12+F13+F14 -> 27 | G24: =G12+G13+G14 -> 33 | H24: =H12+H13+H14 -> 41 | I24: =I12+I13+I14 -> 48 | ... M24: =M12+M13+M14 -> 94 | N24: =SUM(B24:M24) -> 500
A25: Stripe % Fee | B25: =B21*Supuestos!$B$13 -> 0.93351 | C25: =C21*Supuestos!$B$13 -> 2.13353 | D25: =D21*Supuestos!$B$13 -> 3.19493 | E25: =E21*Supuestos!$B$13 -> 4.43004 | F25: =F21*Supuestos!$B$13 -> 5.76085 | G25: =G21*Supuestos!$B$13 -> 6.99596 | H25: =H21*Supuestos!$B$13 -> 8.49758 | I25: =I21*Supuestos!$B$13 -> 10.01428 | ... M25: =M21*Supuestos!$B$13 -> 19.07707 | N25: =SUM(B25:M25) -> 103.58191
A26: Stripe Fixed Fee | B26: =B24*Supuestos!$B$14 -> 1.2 | C26: =C24*Supuestos!$B$14 -> 3 | D26: =D24*Supuestos!$B$14 -> 4.5 | E26: =E24*Supuestos!$B$14 -> 6.3 | F26: =F24*Supuestos!$B$14 -> 8.1 | G26: =G24*Supuestos!$B$14 -> 9.9 | H26: =H24*Supuestos!$B$14 -> 12.3 | I26: =I24*Supuestos!$B$14 -> 14.4 | ... M26: =M24*Supuestos!$B$14 -> 28.2 | N26: =SUM(B26:M26) -> 150
A27: TOTAL STRIPE FEES | B27: =B25+B26 -> 2.13351 | C27: =C25+C26 -> 5.13353 | D27: =D25+D26 -> 7.69493 | E27: =E25+E26 -> 10.73004 | F27: =F25+F26 -> 13.86085 | G27: =G25+G26 -> 16.89596 | H27: =H25+H26 -> 20.79758 | I27: =I25+I26 -> 24.41428 | ... N27: =N25+N26 -> 253.58191
A29: NET REVENUE | B29: =B21-B27 -> 30.05649 | C29: =C21-C27 -> 68.43647 | D29: =D21-D27 -> 102.47507 | E29: =E21-E27 -> 142.02996 | F29: =F21-F27 -> 184.78915 | G29: =G21-G27 -> 224.34404 | H29: =H21-H27 -> 272.22242 | I29: =I21-I27 -> 320.90572 | ... N29: =N21-N27 -> 3318.2081
A31: ═══ COGS (Infrastructure) ═══
A32: Render | B32: =Supuestos!$C$6 -> 7 | C32: =Supuestos!$C$6 -> 7 | D32: =Supuestos!$C$6 -> 7 | E32: =Supuestos!$C$6 -> 7 | F32: =Supuestos!$C$6 -> 7 | G32: =Supuestos!$C$6 -> 7 | H32: =Supuestos!$C$6 -> 7 | I32: =Supuestos!$C$6 -> 7 | ... M32: =Supuestos!$C$6 -> 7 | N32: =SUM(B32:M32) -> 84
A33: Vercel (÷4) | B33: =Supuestos!$C$7 -> 5 | C33: =Supuestos!$C$7 -> 5 | D33: =Supuestos!$C$7 -> 5 | E33: =Supuestos!$C$7 -> 5 | F33: =Supuestos!$C$7 -> 5 | G33: =Supuestos!$C$7 -> 5 | H33: =Supuestos!$C$7 -> 5 | I33: =Supuestos!$C$7 -> 5 | ... M33: =Supuestos!$C$7 -> 5 | N33: =SUM(B33:M33) -> 60
A34: Supabase | B34: =Supuestos!$C$8 -> 0 | C34: =Supuestos!$C$8 -> 0 | D34: =Supuestos!$C$8 -> 0 | E34: =Supuestos!$C$8 -> 0 | F34: =Supuestos!$C$8 -> 0 | G34: =Supuestos!$C$8 -> 0 | H34: =Supuestos!$C$8 -> 0 | I34: =Supuestos!$C$8 -> 0 | ... M34: =Supuestos!$C$8 -> 0 | N34: =SUM(B34:M34) -> 0
A35: Domain | B35: =Supuestos!$C$9 -> 1 | C35: =Supuestos!$C$9 -> 1 | D35: =Supuestos!$C$9 -> 1 | E35: =Supuestos!$C$9 -> 1 | F35: =Supuestos!$C$9 -> 1 | G35: =Supuestos!$C$9 -> 1 | H35: =Supuestos!$C$9 -> 1 | I35: =Supuestos!$C$9 -> 1 | ... M35: =Supuestos!$C$9 -> 1 | N35: =SUM(B35:M35) -> 12
A36: TOTAL COGS | B36: =SUM(B32:B35) -> 13 | C36: =SUM(C32:C35) -> 13 | D36: =SUM(D32:D35) -> 13 | E36: =SUM(E32:E35) -> 13 | F36: =SUM(F32:F35) -> 13 | G36: =SUM(G32:G35) -> 13 | H36: =SUM(H32:H35) -> 13 | I36: =SUM(I32:I35) -> 13 | ... N36: =SUM(N32:N35) -> 156
A38: ═══ GROSS PROFIT ═══
A39: GROSS PROFIT | B39: =B29-B36 -> 17.05649 | C39: =C29-C36 -> 55.43647 | D39: =D29-D36 -> 89.47507 | E39: =E29-E36 -> 129.02996 | F39: =F29-F36 -> 171.78915 | G39: =G29-G36 -> 211.34404 | H39: =H29-H36 -> 259.22242 | I39: =I29-I36 -> 307.90572 | ... N39: =N29-N36 -> 3162.2081
A40: Gross Margin % | B40: =IF(B21>0,B39/B21,0) -> 0.52986921 | C40: =IF(C21>0,C39/C21,0) -> 0.75352005 | D40: =IF(D21>0,D39/D21,0) -> 0.81215458 | E40: =IF(E21>0,E39/E21,0) -> 0.84465803 | F40: =IF(F21>0,F39/F21,0) -> 0.86478304 | G40: =IF(G21>0,G39/G21,0) -> 0.87607379 | H40: =IF(H21>0,H39/H21,0) -> 0.88465777 | I40: =IF(I21>0,I39/I21,0) -> 0.89165331 | ... N40: =IF(N21>0,N39/N21,0) -> 0.88532867
A42: ═══ OPERATING EXPENSES ═══
A43: Marketing/Ads | B43: 50 | C43: 115 | D43: 110 | E43: 100 | F43: 100 | G43: 120 | H43: 120 | I43: 150 | J43: 150 | K43: 180 | L43: 180 | M43: 200 | N43: =SUM(B43:M43) -> 1575
A44: Tools/Software | B44: 0 | C44: 10 | D44: 10 | E44: 10 | F44: 10 | G44: 15 | H44: 15 | I44: 15 | J44: 15 | K44: 20 | L44: 20 | M44: 20 | N44: =SUM(B44:M44) -> 160
A45: TOTAL OPEX | B45: =SUM(B43:B44) -> 50 | C45: =SUM(C43:C44) -> 125 | D45: =SUM(D43:D44) -> 120 | E45: =SUM(E43:E44) -> 110 | F45: =SUM(F43:F44) -> 110 | G45: =SUM(G43:G44) -> 135 | H45: =SUM(H43:H44) -> 135 | I45: =SUM(I43:I44) -> 165 | ... N45: =SUM(N43:N44) -> 1735
A47: ═══ NET INCOME ═══
A48: NET INCOME | B48: =B39-B45 -> -32.94351 | C48: =C39-C45 -> -69.56353 | D48: =D39-D45 -> -30.52493 | E48: =E39-E45 -> 19.02996 | F48: =F39-F45 -> 61.78915 | G48: =G39-G45 -> 76.34404 | H48: =H39-H45 -> 124.22242 | I48: =I39-I45 -> 142.90572 | ... N48: =N39-N45 -> 1427.2081
...

Sheet PL Optimista
A1: P&L - ESCENARIO OPTIMISTA
A2: Incluye: Churn 6% mensual, Marketing OpEx optimista, crecimiento acelerado
A4: Concepto | B4: M1 | C4: M2 | D4: M3 | E4: M4 | F4: M5 | G4: M6 | H4: M7 | I4: M8 | J4: M9 | K4: M10 | L4: M11 | M4: M12 | N4: TOTAL
A5: ═══ SUBSCRIBER DYNAMICS ═══
A6: New Tier 1 Subs (gross) | B6: 4 | C6: 4 | D6: 5 | E6: 5 | F6: 6 | G6: 7 | H6: 8 | I6: 9 | J6: 10 | K6: 12 | L6: 14 | M6: 16
A7: New LATAM Subs (gross) | B7: 4 | C7: 5 | D7: 6 | E7: 7 | F7: 8 | G7: 10 | H7: 12 | I7: 14 | J7: 16 | K7: 18 | L7: 20 | M7: 24
A8: Churned Tier 1 | B8: 0 | C8: =ROUND(B10*Supuestos!$B$25,0) -> 0 | D8: =ROUND(C10*Supuestos!$B$25,0) -> 0 | E8: =ROUND(D10*Supuestos!$B$25,0) -> 1 | F8: =ROUND(E10*Supuestos!$B$25,0) -> 1 | G8: =ROUND(F10*Supuestos!$B$25,0) -> 1 | H8: =ROUND(G10*Supuestos!$B$25,0) -> 2 | I8: =ROUND(H10*Supuestos!$B$25,0) -> 2 | J8: =ROUND(I10*Supuestos!$B$25,0) -> 2 | ... M8: =ROUND(L10*Supuestos!$B$25,0) -> 4
A9: Churned LATAM | B9: 0 | C9: =ROUND(B11*Supuestos!$B$25,0) -> 0 | D9: =ROUND(C11*Supuestos!$B$25,0) -> 1 | E9: =ROUND(D11*Supuestos!$B$25,0) -> 1 | F9: =ROUND(E11*Supuestos!$B$25,0) -> 1 | G9: =ROUND(F11*Supuestos!$B$25,0) -> 2 | H9: =ROUND(G11*Supuestos!$B$25,0) -> 2 | I9: =ROUND(H11*Supuestos!$B$25,0) -> 3 | J9: =ROUND(I11*Supuestos!$B$25,0) -> 3 | ... M9: =ROUND(L11*Supuestos!$B$25,0) -> 6
A10: Active Tier 1 Subs | B10: =B6 -> 4 | C10: =B10+C6-C8 -> 8 | D10: =C10+D6-D8 -> 13 | E10: =D10+E6-E8 -> 17 | F10: =E10+F6-F8 -> 22 | G10: =F10+G6-G8 -> 28 | H10: =G10+H6-H8 -> 34 | I10: =H10+I6-I8 -> 41 | J10: =I10+J6-J8 -> 49 | ... M10: =L10+M6-M8 -> 81 | N10: =M10 -> 81
A11: Active LATAM Subs | B11: =B7 -> 4 | C11: =B11+C7-C9 -> 9 | D11: =C11+D7-D9 -> 14 | E11: =D11+E7-E9 -> 20 | F11: =E11+F7-F9 -> 27 | G11: =F11+G7-G9 -> 35 | H11: =G11+H7-H9 -> 45 | I11: =H11+I7-I9 -> 56 | J11: =I11+J7-J9 -> 69 | ... M11: =L11+M7-M9 -> 116 | N11: =M11 -> 116
A12: Total Active Subs | B12: =B10+B11 -> 8 | C12: =C10+C11 -> 17 | D12: =D10+D11 -> 27 | E12: =E10+E11 -> 37 | F12: =F10+F11 -> 49 | G12: =G10+G11 -> 63 | H12: =H10+H11 -> 79 | I12: =I10+I11 -> 97 | ... N12: =N10+N11 -> 197
A13: Singles sold | B13: 2 | C13: 4 | D13: 5 | E13: 6 | F13: 7 | G13: 8 | H13: 10 | I13: 12 | J13: 14 | K13: 16 | L13: 18 | M13: 20 | N13: =SUM(B13:M13) -> 122
A14: Add-ons sold | B14: 1 | C14: 2 | D14: 3 | E14: 4 | F14: 5 | G14: 6 | H14: 7 | I14: 8 | J14: 10 | K14: 12 | L14: 14 | M14: 16 | N14: =SUM(B14:M14) -> 88
A16: ═══ REVENUE ═══
A17: MRR Tier 1 | B17: =B10*Supuestos!$B$18 -> 42 | C17: =C10*Supuestos!$B$18 -> 84 | D17: =D10*Supuestos!$B$18 -> 136.5 | E17: =E10*Supuestos!$B$18 -> 178.5 | F17: =F10*Supuestos!$B$18 -> 231 | G17: =G10*Supuestos!$B$18 -> 294 | H17: =H10*Supuestos!$B$18 -> 357 | I17: =I10*Supuestos!$B$18 -> 430.5 | ... M17: =M10*Supuestos!$B$18 -> 850.5 | N17: =SUM(B17:M17) -> 4452
A18: MRR LATAM | B18: =B11*Supuestos!$B$19 -> 20.8 | C18: =C11*Supuestos!$B$19 -> 46.8 | D18: =D11*Supuestos!$B$19 -> 72.8 | E18: =E11*Supuestos!$B$19 -> 104 | F18: =F11*Supuestos!$B$19 -> 140.4 | G18: =G11*Supuestos!$B$19 -> 182 | H18: =H11*Supuestos!$B$19 -> 234 | I18: =I11*Supuestos!$B$19 -> 291.2 | ... M18: =M11*Supuestos!$B$19 -> 603.2 | N18: =SUM(B18:M18) -> 2995.2
A19: Singles Revenue | B19: =B13*Supuestos!$B$20 -> 11.98 | C19: =C13*Supuestos!$B$20 -> 23.96 | D19: =D13*Supuestos!$B$20 -> 29.95 | E19: =E13*Supuestos!$B$20 -> 35.94 | F19: =F13*Supuestos!$B$20 -> 41.93 | G19: =G13*Supuestos!$B$20 -> 47.92 | H19: =H13*Supuestos!$B$20 -> 59.9 | I19: =I13*Supuestos!$B$20 -> 71.88 | ... M19: =M13*Supuestos!$B$20 -> 119.8 | N19: =SUM(B19:M19) -> 730.78
A20: Add-ons Revenue | B20: =B14*Supuestos!$B$21 -> 3.99 | C20: =C14*Supuestos!$B$21 -> 7.98 | D20: =D14*Supuestos!$B$21 -> 11.97 | E20: =E14*Supuestos!$B$21 -> 15.96 | F20: =F14*Supuestos!$B$21 -> 19.95 | G20: =G14*Supuestos!$B$21 -> 23.94 | H20: =H14*Supuestos!$B$21 -> 27.93 | I20: =I14*Supuestos!$B$21 -> 31.92 | ... M20: =M14*Supuestos!$B$21 -> 63.84 | N20: =SUM(B20:M20) -> 351.12
A21: TOTAL REVENUE | B21: =SUM(B17:B20) -> 78.77 | C21: =SUM(C17:C20) -> 162.74 | D21: =SUM(D17:D20) -> 251.22 | E21: =SUM(E17:E20) -> 334.4 | F21: =SUM(F17:F20) -> 433.28 | G21: =SUM(G17:G20) -> 547.86 | H21: =SUM(H17:H20) -> 678.83 | I21: =SUM(I17:I20) -> 825.5 | ... N21: =SUM(N17:N20) -> 8529.1
A23: ═══ COST OF REVENUE (Stripe) ═══
A24: Transactions | B24: =B12+B13+B14 -> 11 | C24: =C12+C13+C14 -> 23 | D24: =D12+D13+D14 -> 35 | E24: =E12+E13+E14 -> 47 | F24: =F12+F13+F14 -> 61 | G24: =G12+G13+G14 -> 77 | H24: =H12+H13+H14 -> 96 | I24: =I12+I13+I14 -> 117 | ... M24: =M12+M13+M14 -> 233 | N24: =SUM(B24:M24) -> 1210
A25: Stripe % Fee | B25: =B21*Supuestos!$B$13 -> 2.28433 | C25: =C21*Supuestos!$B$13 -> 4.71946 | D25: =D21*Supuestos!$B$13 -> 7.28538 | E25: =E21*Supuestos!$B$13 -> 9.6976 | F25: =F21*Supuestos!$B$13 -> 12.56512 | G25: =G21*Supuestos!$B$13 -> 15.88794 | H25: =H21*Supuestos!$B$13 -> 19.68607 | I25: =I21*Supuestos!$B$13 -> 23.9395 | ... M25: =M21*Supuestos!$B$13 -> 47.48286 | N25: =SUM(B25:M25) -> 247.3439
A26: Stripe Fixed Fee | B26: =B24*Supuestos!$B$14 -> 3.3 | C26: =C24*Supuestos!$B$14 -> 6.9 | D26: =D24*Supuestos!$B$14 -> 10.5 | E26: =E24*Supuestos!$B$14 -> 14.1 | F26: =F24*Supuestos!$B$14 -> 18.3 | G26: =G24*Supuestos!$B$14 -> 23.1 | H26: =H24*Supuestos!$B$14 -> 28.8 | I26: =I24*Supuestos!$B$14 -> 35.1 | ... M26: =M24*Supuestos!$B$14 -> 69.9 | N26: =SUM(B26:M26) -> 363
A27: TOTAL STRIPE FEES | B27: =B25+B26 -> 5.58433 | C27: =C25+C26 -> 11.61946 | D27: =D25+D26 -> 17.78538 | E27: =E25+E26 -> 23.7976 | F27: =F25+F26 -> 30.86512 | G27: =G25+G26 -> 38.98794 | H27: =H25+H26 -> 48.48607 | I27: =I25+I26 -> 59.0395 | ... N27: =N25+N26 -> 610.3439
A29: NET REVENUE | B29: =B21-B27 -> 73.18567 | C29: =C21-C27 -> 151.12054 | D29: =D21-D27 -> 233.43462 | E29: =E21-E27 -> 310.6024 | F29: =F21-F27 -> 402.41488 | G29: =G21-G27 -> 508.87206 | H29: =H21-H27 -> 630.34393 | I29: =I21-I27 -> 766.4605 | ... N29: =N21-N27 -> 7918.7561
A31: ═══ COGS (Infrastructure) ═══
A32: Render | B32: =Supuestos!$C$6 -> 7 | C32: =Supuestos!$C$6 -> 7 | D32: =Supuestos!$C$6 -> 7 | E32: =Supuestos!$C$6 -> 7 | F32: =Supuestos!$C$6 -> 7 | G32: =Supuestos!$C$6 -> 7 | H32: =Supuestos!$C$6 -> 7 | I32: =Supuestos!$C$6 -> 7 | ... M32: =Supuestos!$C$6 -> 7 | N32: =SUM(B32:M32) -> 84
A33: Vercel (÷4) | B33: =Supuestos!$C$7 -> 5 | C33: =Supuestos!$C$7 -> 5 | D33: =Supuestos!$C$7 -> 5 | E33: =Supuestos!$C$7 -> 5 | F33: =Supuestos!$C$7 -> 5 | G33: =Supuestos!$C$7 -> 5 | H33: =Supuestos!$C$7 -> 5 | I33: =Supuestos!$C$7 -> 5 | ... M33: =Supuestos!$C$7 -> 5 | N33: =SUM(B33:M33) -> 60
A34: Supabase | B34: =Supuestos!$C$8 -> 0 | C34: =Supuestos!$C$8 -> 0 | D34: =Supuestos!$C$8 -> 0 | E34: =Supuestos!$C$8 -> 0 | F34: =Supuestos!$C$8 -> 0 | G34: =Supuestos!$C$8 -> 0 | H34: =Supuestos!$C$8 -> 0 | I34: =Supuestos!$C$8 -> 0 | ... M34: =Supuestos!$C$8 -> 0 | N34: =SUM(B34:M34) -> 0
A35: Domain | B35: =Supuestos!$C$9 -> 1 | C35: =Supuestos!$C$9 -> 1 | D35: =Supuestos!$C$9 -> 1 | E35: =Supuestos!$C$9 -> 1 | F35: =Supuestos!$C$9 -> 1 | G35: =Supuestos!$C$9 -> 1 | H35: =Supuestos!$C$9 -> 1 | I35: =Supuestos!$C$9 -> 1 | ... M35: =Supuestos!$C$9 -> 1 | N35: =SUM(B35:M35) -> 12
A36: TOTAL COGS | B36: =SUM(B32:B35) -> 13 | C36: =SUM(C32:C35) -> 13 | D36: =SUM(D32:D35) -> 13 | E36: =SUM(E32:E35) -> 13 | F36: =SUM(F32:F35) -> 13 | G36: =SUM(G32:G35) -> 13 | H36: =SUM(H32:H35) -> 13 | I36: =SUM(I32:I35) -> 13 | ... N36: =SUM(N32:N35) -> 156
A38: ═══ GROSS PROFIT ═══
A39: GROSS PROFIT | B39: =B29-B36 -> 60.18567 | C39: =C29-C36 -> 138.12054 | D39: =D29-D36 -> 220.43462 | E39: =E29-E36 -> 297.6024 | F39: =F29-F36 -> 389.41488 | G39: =G29-G36 -> 495.87206 | H39: =H29-H36 -> 617.34393 | I39: =I29-I36 -> 753.4605 | ... N39: =N29-N36 -> 7762.7561
A40: Gross Margin % | B40: =IF(B21>0,B39/B21,0) -> 0.76406843 | C40: =IF(C21>0,C39/C21,0) -> 0.84871906 | D40: =IF(D21>0,D39/D21,0) -> 0.87745649 | E40: =IF(E21>0,E39/E21,0) -> 0.88995933 | F40: =IF(F21>0,F39/F21,0) -> 0.89876034 | G40: =IF(G21>0,G39/G21,0) -> 0.90510725 | H40: =IF(H21>0,H39/H21,0) -> 0.90942346 | I40: =IF(I21>0,I39/I21,0) -> 0.91273228 | ... N40: =IF(N21>0,N39/N21,0) -> 0.9101495
A42: ═══ OPERATING EXPENSES ═══
A43: Marketing/Ads | B43: 90 | C43: 200 | D43: 230 | E43: 200 | F43: 200 | G43: 250 | H43: 250 | I43: 300 | J43: 300 | K43: 350 | L43: 350 | M43: 400 | N43: =SUM(B43:M43) -> 3120
A44: Tools/Software | B44: 0 | C44: 15 | D44: 15 | E44: 15 | F44: 20 | G44: 20 | H44: 20 | I44: 25 | J44: 25 | K44: 25 | L44: 30 | M44: 30 | N44: =SUM(B44:M44) -> 240
A45: TOTAL OPEX | B45: =SUM(B43:B44) -> 90 | C45: =SUM(C43:C44) -> 215 | D45: =SUM(D43:D44) -> 245 | E45: =SUM(E43:E44) -> 215 | F45: =SUM(F43:F44) -> 220 | G45: =SUM(G43:G44) -> 270 | H45: =SUM(H43:H44) -> 270 | I45: =SUM(I43:I44) -> 325 | ... N45: =SUM(N43:N44) -> 3360
A47: ═══ NET INCOME ═══
A48: NET INCOME | B48: =B39-B45 -> -29.81433 | C48: =C39-C45 -> -76.87946 | D48: =D39-D45 -> -24.56538 | E48: =E39-E45 -> 82.6024 | F48: =F39-F45 -> 169.41488 | G48: =G39-G45 -> 225.87206 | H48: =H39-H45 -> 347.34393 | I48: =I39-I45 -> 428.4605 | ... N48: =N39-N45 -> 4402.7561
...

Sheet Comparación
A1: COMPARACIÓN DE ESCENARIOS
A3: Métrica | B3: Base | C3: Optimista | D3: Diferencia
A4: Total Revenue Año 1 | B4: ='PL Base (Conservador)'!N21 -> 3571.79 | C4: ='PL Optimista'!N21 -> 8529.1 | D4: =C4-B4 -> 4957.31
A5: Total Stripe Fees | B5: ='PL Base (Conservador)'!N27 -> 253.58191 | C5: ='PL Optimista'!N27 -> 610.3439 | D5: =C5-B5 -> 356.76199
A6: Total COGS | B6: ='PL Base (Conservador)'!N36 -> 156 | C6: ='PL Optimista'!N36 -> 156 | D6: =C6-B6 -> 0
A7: Gross Profit | B7: ='PL Base (Conservador)'!N39 -> 3162.2081 | C7: ='PL Optimista'!N39 -> 7762.7561 | D7: =C7-B7 -> 4600.548
A8: Marketing OpEx | B8: ='PL Base (Conservador)'!N43 -> 1575 | C8: ='PL Optimista'!N43 -> 3120 | D8: =C8-B8 -> 1545
A9: Tools/Software | B9: ='PL Base (Conservador)'!N44 -> 160 | C9: ='PL Optimista'!N44 -> 240 | D9: =C9-B9 -> 80
A10: Total OpEx | B10: ='PL Base (Conservador)'!N45 -> 1735 | C10: ='PL Optimista'!N45 -> 3360 | D10: =C10-B10 -> 1625
A11: Net Income Año 1 | B11: ='PL Base (Conservador)'!N48 -> 1427.2081 | C11: ='PL Optimista'!N48 -> 4402.7561 | D11: =C11-B11 -> 2975.548
A13: MRR Mes 12 | B13: ='PL Base (Conservador)'!B54 -> 570 | C13: ='PL Optimista'!B54 -> 1453.7 | D13: =C13-B13 -> 883.7
A14: ARR Proyectado | B14: =B13*12 -> 6840 | C14: =C13*12 -> 17444.4 | D14: =C14-B14 -> 10604.4
A15: Active Subs Mes 12 | B15: ='PL Base (Conservador)'!M12 -> 77 | C15: ='PL Optimista'!M12 -> 197 | D15: =C15-B15 -> 120
A17: Gross Margin % | B17: ='PL Base (Conservador)'!N39/'PL Base (Conservador)'!N21 -> 0.88532867 | C17: ='PL Optimista'!N39/'PL Optimista'!N21 -> 0.9101495 | D17: =C17-B17 -> 0.02482083
A18: Net Margin % | B18: ='PL Base (Conservador)'!N48/'PL Base (Conservador)'!N21 -> 0.39957783 | C18: ='PL Optimista'!N48/'PL Optimista'!N21 -> 0.51620407 | D18: =C18-B18 -> 0.11662624
A22: KEY INSIGHTS
A23: • Churn 6% reduce subs activos ~25-30% vs sin churn
A24: • Marketing + Tools OpEx absorbe utilidad en meses tempranos
A25: • Base: net positive desde Mes 4, Optimista: net positive desde Mes 3
A26: • Escenario optimista: ~$11/sub adicional CAC, payback <2 meses
A27: • Gross margin 75-80% es excelente para SaaS bootstrapped
A28: • Tools: Email service (Resend/SendGrid) necesario desde M2
